Workbook

Sheet Enterprise-Plans-Product-APN
E1: Product type names
A2: # | B2: Enterprise Name | C2: Billing cycle date | D2: Device plan names | E2: SIM 2G/3G | F2: SIM LTE | G2: SIM CLARO | H2: APN #1 | I2: APN #2 | J2: APN #3 | K2: APN Type
A3: 1 | B3: 24HS SA | C3: 8 | D3: =VLOOKUP(B3,Hoja1!A:C,2,FALSE) -> 1 (JASC010) | E3: 396 | F3: 0 | G3: 0 | H3: m2m.amx | I3: 24HS.M2M.CLARO.COM.AR | J3: --- | K3: PUBLIC
A4: 2 | B4: ACRONEX S.R.L. | C4: 8 | D4: =VLOOKUP(B4,Hoja1!A:C,2,FALSE) -> 2 (JANU025, JARA050) | E4: 2650 | F4: 0 | G4: 0 | H4: SLABOCH.G.CLARO.COM.AR | I4: --- | J4: --- | K4: PRIVATE
A5: 3 | B5: A.C. SAT SRL | C5: 8 | D5: =VLOOKUP(B5,Hoja1!A:C,2,FALSE) -> 1 JASC010 | E5: 9600 | F5: 0 | G5: 0 | H5: ACSAT.M2M.CLARO.COM.AR | I5: m2m.amx | J5: --- | K5: PUBLIC
A6: 4 | B6: AGUAS CORDOBESAS SA | C6: 8 | D6: =VLOOKUP(B6,Hoja1!A:C,2,FALSE) -> 1 (JASC010) | E6: 310 | F6: 0 | G6: 0 | H6: m2m.amx | I6: --- | J6: --- | K6: PUBLIC
A7: 5 | B7: AGUA Y SANEAMIENTOS ARGENTINOSSOCIEDAD ANONIMA | C7: 8 | D7: =VLOOKUP(B7,Hoja1!A:C,2,FALSE) -> 3 (JASI050, JASI1GB, JASI500) | E7: 1153 | F7: 0 | G7: 0 | H7: aysa.m2m.claro.com.ar | I7: --- | J7: --- | K7: PRIVATE
A8: 6 | B8: ALAR SUR SRL | C8: 8 | D8: =VLOOKUP(B8,Hoja1!A:C,2,FALSE) -> 3 (JANU050, JASC010, JASC025) | E8: 700 | F8: 0 | G8: 0 | H8: ALARSUR.M2M.CLARO.COM.AR | I8: --- | J8: --- | K8: PRIVATE
A9: 7 | B9: Albiero Hnos SRL | C9: 8 | D9: =VLOOKUP(B9,Hoja1!A:C,2,FALSE) -> 1 (JASC010) | E9: 997 | F9: 100 | G9: 0 | H9: albiero.claro.com.ar | I9: m2m.amx | J9: --- | K9: PUBLIC
A10: 8 | B10: AMERICA GIS SRL | C10: 8 | D10: =VLOOKUP(B10,Hoja1!A:C,2,FALSE) -> 1 (JASC010) | E10: 850 | F10: 50 | G10: 0 | H10: clarom2m.com | I10: m2m.amx | J10: --- | K10: PUBLIC
A11: 9 | B11: AXAN S.A. | C11: 8 | D11: =VLOOKUP(B11,Hoja1!A:C,2,FALSE) -> 1 (JASC025) | E11: 500 | F11: 0 | G11: 0 | H11: ALESAT.M2M.CLARO.COM.AR | I11: --- | J11: --- | K11: PRIVATE
A12: 10 | B12: BANCO DE LA PROVINCIA DE BS AS | C12: 8 | D12: =VLOOKUP(B12,Hoja1!A:C,2,FALSE) -> 1 (JASB1GB) | E12: 0 | F12: 0 | G12: 482 | H12: clarom2m.com | I12: m2m.amx | J12: --- | K12: PUBLIC
A13: 11 | B13: BAUMBACH BRIAN LEANDRO | C13: 8 | D13: =VLOOKUP(B13,Hoja1!A:C,2,FALSE) -> 1 (JASC010) | E13: 100 | F13: 170 | G13: 0 | H13: clarom2m.com | I13: m2m.amx | J13: --- | K13: PUBLIC
A14: 12 | B14: BIT S.A. | C14: 8 | D14: =VLOOKUP(B14,Hoja1!A:C,2,FALSE) -> 2 (JASC010 y JASC025) | E14: 1050 | F14: 0 | G14: 0 | H14: bitsa.claro.com.ar | I14: --- | J14: --- | K14: PRIVATE
A15: 13 | B15: BOBADILLA ALEJANDRO CESAR | C15: 8 | D15: 1(JASC025) | E15: 100 | F15: 0 | G15: 0 | H15: clarom2m.com | I15: m2m.amx | J15: --- | K15: PUBLIC
A16: 14 | B16: BUGS SOLUCIONES ELECT SA | C16: 8 | D16: =VLOOKUP(B16,Hoja1!A:C,2,FALSE) -> 2 (JASC010, JASC025) | E16: 549 | F16: 0 | G16: 0 | H16: m2m.amx | I16: --- | J16: --- | K16: PUBLIC
A17: 15 | B17: CENTRAL DE OP. MULTIPLES SRL | C17: 8 | D17: =VLOOKUP(B17,Hoja1!A:C,2,FALSE) -> 2 (JASC010, JASC025) | E17: 350 | F17: 0 | G17: 0 | H17: CENTRALSRL.M2M.CLARO.COM.AR | I17: --- | J17: --- | K17: PRIVATE
A18: 16 | B18: COMPAÑIA OMNIBUS 25 DE MAYO LINEA 278 SA | C18: 8 | D18: 1(JASC025) | E18: 250 | F18: 0 | G18: 0 | H18: COVEMA.M2M.CLARO.COM.AR | I18: --- | J18: --- | K18: PRIVATE
A19: 17 | B19: COM SEG ARGENTINA S.A.S. | C19: 8 | D19: =VLOOKUP(B19,Hoja1!A:C,2,FALSE) -> 2 (JANU050, JASC010) | E19: 500 | F19: 0 | G19: 0 | H19: clarom2m.com | I19: m2m.amx | J19: --- | K19: PUBLIC
A20: 18 | B20: COMUNIDAT SAS | C20: 8 | D20: =VLOOKUP(B20,Hoja1!A:C,2,FALSE) -> 3 (JASC010, JASC100, JASC1GB) | E20: 100 | F20: 0 | G20: 0 | H20: apncdt01.m2m.claro.com.ar | I20: --- | J20: --- | K20: PRIVATE
A21: 19 | B21: CROSS SRL | C21: 8 | D21: =VLOOKUP(B21,Hoja1!A:C,2,FALSE) -> 1 (JANU0500) | E21: 1015 | F21: 0 | G21: 0 | H21: GCROSS.M2M.CLARO.COM.AR | I21: --- | J21: --- | K21: PRIVATE
A22: 20 | B22: DEPARTAMENTO GRAL IRRIGACION | C22: 8 | D22: =VLOOKUP(B22,Hoja1!A:C,2,FALSE) -> 1 (JASC010) | E22: 300 | F22: 0 | G22: 0 | H22: irrigacion.m2m.claro.com.ar | I22: --- | J22: --- | K22: PRIVATE
A23: 21 | B23: DESARROLLOS DEL LITORAL SA | C23: 8 | D23: =VLOOKUP(B23,Hoja1!A:C,2,FALSE) -> #N/A | E23: 330 | F23: 0 | G23: 0 | H23: DLITORALSA.M2M.CLARO.COM.AR | I23: --- | J23: --- | K23: PRIVATE
A24: 22 | B24: DI BELLA, LUCAS GASTON | C24: 8 | D24: =VLOOKUP(B24,Hoja1!A:C,2,FALSE) -> 1 (JASC010) | E24: 100 | F24: 0 | G24: 0 | H24: clarom2m.com | I24: m2m.amx | J24: --- | K24: PUBLIC
A25: 23 | B25: DISCAR S.A. | C25: 8 | D25: =VLOOKUP(B25,Hoja1!A:C,2,FALSE) -> 1 (JANU025) | E25: 1611 | F25: 100 | G25: 0 | H25: DISCAR.M2M.CLARO.COM.AR | I25: --- | J25: --- | K25: PRIVATE
A26: 24 | B26: ECOHABITAT S.A Y OTRA UNION TRANSITORIA | C26: 8 | D26: =VLOOKUP(B26,Hoja1!A:C,2,FALSE) -> 1 (JANU050) | E26: 100 | F26: 0 | G26: 0 | H26: ECOHAB.M2M.CLARO.COM.AR | I26: --- | J26: --- | K26: PRIVATE
A27: 25 | B27: EDENOR S.A. | C27: 8 | D27: =VLOOKUP(B27,Hoja1!A:C,2,FALSE) -> 1 (JASC025) | E27: 550 | F27: 0 | G27: 0 | H27: edenor.m2m.claro.com.ar | I27: --- | J27: --- | K27: PRIVATE
A28: 26 | B28: EDENRED ARGENTINA SOCIEDAD ANONIMA | C28: 8 | D28: =VLOOKUP(B28,Hoja1!A:C,2,FALSE) -> 1 (JASC025) | E28: 1520 | F28: 0 | G28: 0 | H28: EDENRED2.M2M.CLARO.COM.AR | I28: --- | J28: --- | K28: PRIVATE
A29: 27 | B29: EDESA S.A. | C29: 8 | D29: =VLOOKUP(B29,Hoja1!A:C,2,FALSE) -> 1 (JASC010) | E29: 400 | F29: 0 | G29: 0 | H29: edesamedidores.m2m.claro.com.ar | I29: --- | J29: --- | K29: PRIVATE
A30: 28 | B30: EDES SA | C30: 8 | D30: =VLOOKUP(B30,Hoja1!A:C,2,FALSE) -> 1 (JASC010) | E30: 4705 | F30: 0 | G30: 0 | H30: edesmedclaro.m2m.claro.com.ar | I30: edestelclaro.m2m.claro.com.ar | J30: --- | K30: PRIVATE
... A64: 62 | B64: MUNICIPALIDAD DE ROSARIO | C64: 8 | D64: =VLOOKUP(B64,Hoja1!A:C,2,FALSE) -> 1 (JASC025) | E64: 745 | F64: 0 | G64: 0 | H64: clarom2m.com | I64: m2m.amx | J64: --- | K64: PUBLIC
A65: 63 | B65: Nación Servicio Posnet | C65: 8 | D65: 1(JAPO500) | E65: 0 | F65: 0 | G65: 16000 | H65: m2m.amx | I65: --- | J65: --- | K65: PUBLIC
A66: 64 | B66: NACION SERVICIOS SA | C66: 8 | D66: =VLOOKUP(B66,Hoja1!A:C,2,FALSE) -> 4 (SUBE050, JANS025, JANS050, JAP0500) | E66: 2905 | F66: 0 | G66: 0 | H66: NACIONSERV.M2M.CLARO.COM.AR | I66: --- | J66: --- | K66: PRIVATE
A67: 65 | B67: Nacion Servicios – Solución Especial LTE | C67: 8 | D67: 2(JANS025,JANS050,JANSGB2,JANS2GB) | E67: 0 | F67: 0 | G67: 40700 | H67: clarom2m.com | I67: --- | J67: --- | K67: PRIVATE
A68: 66 | B68: NOVIT S.A. | C68: 8 | D68: =VLOOKUP(B68,Hoja1!A:C,2,FALSE) -> 1 (JASC010) | E68: 1300 | F68: 0 | G68: 0 | H68: novitsa.m2m.claro.com.ar | I68: m2m.amx | J68: --- | K68: PUBLIC
A69: 67 | B69: N.T.B.SA | C69: 8 | D69: =VLOOKUP(B69,Hoja1!A:C,2,FALSE) -> 1 (JASC010) | E69: 1405 | F69: 0 | G69: 0 | H69: ntbm2m.claro.com.ar | I69: --- | J69: --- | K69: PRIVATE
A70: 68 | B70: OLEIROS SA | C70: 8 | D70: =VLOOKUP(B70,Hoja1!A:C,2,FALSE) -> 1 (LOJ015+) | E70: 501196 | F70: 0 | G70: 102085 | H70: OLEIROS.M2M.CLARO.COM.AR | I70: clarom2m.com | J70: --- | K70: PRIVATE
A71: 69 | B71: ORMACHEA CARLOS EZEQUIEL | C71: 8 | D71: =VLOOKUP(B71,Hoja1!A:C,2,FALSE) -> 1 (JASC010) | E71: 505 | F71: 150 | G71: 0 | H71: ORMACHEAM2M.CLARO.COM.AR | I71: --- | J71: --- | K71: PRIVATE
A72: 70 | B72: PAGO VIRTUAL DEL SUR S.A | C72: 8 | D72: =VLOOKUP(B72,Hoja1!A:C,2,FALSE) -> 1 (JASC025) | E72: 600 | F72: 0 | G72: 0 | H72: m2m.amx | I72: --- | J72: --- | K72: PUBLIC
A73: 71 | B73: PAN AMERICAN ENERGY SL SUCURSAL ARGENTIN A | C73: 8 | D73: =VLOOKUP(B73,Hoja1!A:C,2,FALSE) -> 1 (JASC010) | E73: 200 | F73: 0 | G73: 0 | H73: AXION.CLARO.COM.AR | I73: --- | J73: --- | K73: PRIVATE
...

Sheet Rule Engine
A1: Created By Account | B1: Rule Name | C1: Category | D1: Trigger | E1: Creation Date | F1: Action | G1: Rule Definition | H1: Filters | I1: Active
A2: 24HS SA | B2: De "Listo para activar" a "Activado"; sms: BWS.off | C2: SIM Provisioning | D2: SIM State Change | E2: 10/29/2019 | F2: Send an SMS | G2: From Activation Ready; To Activated | H2: Account: 24HS SA | I2: Yes
A3: 24HS SA | B3: Email por exceso a JL. | C3: Usage Monitoring | D3: Cycle To Date Data Usage | E3: 10/29/2019 | F3: Send an email to jl@24hs.com.ar | G3: Data usage approaches its usage limit 10240 KB | H3: Account: 24HS SA | I3: Yes
A4: 24HS SA | B4: Enviar eMail a TEC de "activado" de la SIM. | C4: SIM Provisioning | D4: SIM State Change | E4: 10/29/2019 | F4: Send an email to tec@24hs.com.ar | G4: From Activation Ready; To Activated | H4: Account: 24HS SA | I4: Yes
A5: ACRONEX S.R.L. | B5: Chip Activado | C5: SIM Provisioning | D5: SIM State Change | E5: 08/01/2024 | F5: Push an API message to http://unimap.acronex.com/jasper_push_api?jasper_id=2 | G5: From Any; To Activated | H5: Account: ACRONEX S.R.L. | I5: Yes
A6: ACRONEX S.R.L. | B6: Chip a Inventario | C6: SIM Provisioning | D6: SIM State Change | E6: 08/02/2024 | F6: Push an API message to http://unimap.acronex.com/jasper_push_api?jasper_id=2 | G6: From Any; To Inventory | H6: Account: ACRONEX S.R.L. | I6: Yes
A7: ACRONEX S.R.L. | B7: Chip Listo para activar | C7: SIM Provisioning | D7: SIM State Change | E7: 08/02/2024 | F7: Push an API message to http://unimap.acronex.com/jasper_push_api?jasper_id=2 | G7: From Any; To Activation Ready | H7: Account: ACRONEX S.R.L. | I7: Yes
A8: ACRONEX S.R.L. | B8: Cambio de IMEI | C8: Security | D8: IMEI Change | E8: 08/02/2024 | F8: Push an API message to http://unimap.acronex.com/jasper_push_api?jasper_id=2 | G8: Trigger when detecting an IMEI change in accounting start request | H8: Account: ACRONEX S.R.L. | I8: Yes
A9: ACRONEX S.R.L. | B9: Chip Desactivado | C9: SIM Provisioning | D9: SIM State Change | E9: 08/02/2024 | F9: Push an API message to http://unimap.acronex.com/jasper_push_api?jasper_id=2 | G9: From Any; To Deactivated | H9: Account: ACRONEX S.R.L. | I9: Yes
A10: BANCO DE LA PROVINCIA DE BS AS | B10: SIM_ACTIVADA | C10: SIM Provisioning | D10: SIM State Change | E10: 12/01/2023 | F10: Send an email to etorres2@bpba.com.ar,ccereto@bpba.com.ar | G10: From Test Ready; To Activated | H10: Account: BANCO DE LA PROVINCIA DE BS AS | I10: Yes
A11: BAUMBACH BRIAN LEANDRO | B11: ALERTA - Aviso de cambio de IMEI | C11: Security | D11: IMEI Change | E11: 12/05/2024 | F11: Send an email to brian@pampasat.com | G11: Trigger when detecting an IMEI change in accounting start request | H11: Account: BAUMBACH BRIAN LEANDRO; Sim Status: Activated | I11: Yes
A12: BAUMBACH BRIAN LEANDRO | B12: AVISO - Exceso diario de MB | C12: Usage Monitoring | D12: Recent Data Usage (24 hours) | E12: 12/06/2024 | F12: Send an email to brian@pampasat.com | G12: 512 KB data usage in 24 hours | H12: Account: BAUMBACH BRIAN LEANDRO; Sim Status: Activated | I12: Yes
... A44: NACION SERVICIOS SA | B44: Alerta de Consumo de Datos (excedente) - 50MB | C44: Usage Monitoring | D44: Cycle To Date Data Usage | E44: 01/27/2016 | F44: Send an email to acomunicaciones@nacionservicios.com.ar,aalertasdesactivacionsim@nacionservicios.com.ar,asoportederedesdecarga-tas@nacionservicios.com.ar,asoportederedesdeuso@nacionservicios.com.ar | G44: Data usage exceeds a specified limit 51200 KB | H44: Account: NACION SERVICIOS SA; Sim Status: Activated | I44: Yes
A45: Nacion Servicios – Solución Especial LTE | B45: Cambio de plan para contrataciones nuevas | C45: SIM Provisioning | D45: SIM Rate Plan Change | E45: 03/23/2018 | F45: Send an email to ACOMUNICACIONES@nacionservicios.com.ar | H45: Account: Nacion Servicios – Solución Especial LTE | I45: Yes
A46: Nacion Servicios – Solución Especial LTE | B46: Pase a Listo para activar si no tiene conexion por 1 mes para GARAJES y TAS | C46: Usage Monitoring | D46: No connection | E46: 04/21/2023 | F46: Change the SIM status to "Activation Ready" | G46: Maximum no connection hours is 720 | H46: Account: NACION SERVICIOS SA; Sim Status: Activated | I46: Yes
A47: Nacion Servicios – Solución Especial LTE | B47: Pase a Listo para activar si no tiene conexion por 1 mes para GDF | C47: Usage Monitoring | D47: No connection | E47: 04/21/2023 | F47: Change the SIM status to "Activation Ready" | G47: Maximum no connection hours is 720 | H47: Account: Nacion Servicios – Solución Especial LTE; Sim Status: Activated | I47: Yes
A48: Nacion Servicios – Solución Especial LTE | B48: Sin conexion de SIM por mas de 24 hs | C48: Usage Monitoring | D48: No connection | E48: 04/03/2023 | F48: Send an email to cfigueroa@nacionservicios.com.ar,lmachado@nacionservicios.com.ar,hetala@nacionservicios.com.ar,sfernandez@nacionservicios.com.ar | G48: Maximum no connection hours is 24 | H48: Account: NACION SERVICIOS SA; Rate Plan: SUBE050; Sim Status: Activated; Comentarios: GARAJE | I48: Yes
A49: Nacion Servicios – Solución Especial LTE | B49: Desactivacion de SIM Camaras - 100% | C49: Usage Monitoring | D49: Cycle To Date Data Usage | E49: 12/27/2018 | F49: Change the SIM status to "Deactivated" | G49: Data usage exceeds a specified limit 2000000 KB | H49: Account: Nacion Servicios – Solución Especial LTE; Rate Plan: JANS2GB | I49: Yes
A50: Nacion Servicios – Solución Especial LTE | B50: Desactivacion de SIM Validador GPS - 100% | C50: Usage Monitoring | D50: Cycle To Date Data Usage | E50: 12/27/2018 | F50: Change the SIM status to "Deactivated" | G50: Data usage exceeds a specified limit 100000 KB | H50: Account: Nacion Servicios – Solución Especial LTE; Rate Plan: JANS050 | I50: Yes
A51: Nacion Servicios – Solución Especial LTE | B51: Desactivacion de SIM Gestion de Flota - 100% | C51: Usage Monitoring | D51: Cycle To Date Data Usage | E51: 12/27/2018 | F51: Change the SIM status to "Deactivated" | G51: Data usage exceeds a specified limit 256000 KB | H51: Account: Nacion Servicios – Solución Especial LTE; Rate Plan: JANS025 | I51: Yes
A52: Nacion Servicios – Solución Especial LTE | B52: SIM 50MB Validador GPS - Desactivacion (100%) | C52: Usage Monitoring | D52: Cycle To Date Data Usage | E52: 12/27/2018 | F52: Send an email to acomunicaciones@nacionservicios.com.ar,mgimenez@nacionservicios.com.ar,llopinto@nacionservicios.com.ar,mmiranda@nacionservicios.com.ar | G52: Data usage exceeds a specified limit 100000 KB | H52: Account: Nacion Servicios – Solución Especial LTE; Rate Plan: JANS050 | I52: Yes
A53: Nacion Servicios – Solución Especial LTE | B53: SIM 25MB Gestion de Flota - Desactivacion (100%) | C53: Usage Monitoring | D53: Cycle To Date Data Usage | E53: 12/27/2018 | F53: Send an email to acomunicaciones@nacionservicios.com.ar,mgimenez@nacionservicios.com.ar,llopinto@nacionservicios.com.ar,mmiranda@nacionservicios.com.ar | G53: Data usage exceeds a specified limit 256000 KB | H53: Account: Nacion Servicios – Solución Especial LTE; Rate Plan: JANS025 | I53: Yes
A54: Nacion Servicios – Solución Especial LTE | B54: SIM 50MB Validador GPS - Desactivacion (40%) | C54: Usage Monitoring | D54: Cycle To Date Data Usage | E54: 03/23/2018 | F54: Send an email to acomunicaciones@nacionservicios.com.ar,CBARGIELA@nacionservicios.com.ar | G54: Data usage exceeds a specified limit 70000 KB | H54: Account: Nacion Servicios – Solución Especial LTE; Rate Plan: JANS050 | I54: Yes
A55: Nacion Servicios – Solución Especial LTE | B55: Desactivacion de SIM Validador GPS | C55: Usage Monitoring | D55: Cycle To Date Data Usage | E55: 03/23/2018 | F55: Change the SIM status to "Deactivated" | G55: Data usage exceeds a specified limit 70000 KB | H55: Account: Nacion Servicios – Solución Especial LTE; Rate Plan: JANS050 | I55: Yes
A56: OLEIROS SA | B56: Test | C56: SIM Provisioning | D56: SIM State Change | E56: 09/23/2015 | F56: Change the SIM State to "Activation Ready" at coming UTC "22:00" | G56: From Test Ready; To Inventory | H56: Account: OLEIROS SA | I56: Yes
A57: OLEIROS SA | B57: Rango de direcciones IP | C57: Network and System | D57: Available Static IP Addresses | E57: 11/22/2023 | F57: Send an email to rbarrios@strix.com.ar | G57: Trigger if the number of available static IP addresses falls below 5000. | H57: Account: OLEIROS SA | I57: Yes
... A61: ORMACHEA CARLOS EZEQUIEL | B61: Cambio de "Listo para Activar" a "Activado" | C61: SIM Provisioning | D61: SIM State Change | E61: 07/28/2016 | F61: Send an email to soporte@tecnologiaintegrada.com | G61: From Activation Ready; To Activated | H61: Account: ORMACHEA CARLOS EZEQUIEL | I61: Yes
A62: ORMACHEA CARLOS EZEQUIEL | B62: Cambio de planes de precios | C62: SIM Provisioning | D62: SIM Rate Plan Change | E62: 12/04/2015 | F62: Send an email to eormachea@exsoft.com.ar | H62: Account: ORMACHEA CARLOS EZEQUIEL | I62: Yes
A63: PROSEGUR ACTIVA ARGENTINA SA | B63: CAMBIO DE EQUIPO | C63: Security | D63: IMEI Change | E63: 06/22/2017 | F63: Change the SIM status to "Deactivated" | G63: Trigger when detecting an IMEI change in accounting start request | H63: Account: PROSEGUR ACTIVA ARGENTINA SA | I63: Yes
A64: PROSEGUR ACTIVA ARGENTINA SA | B64: Exceso SMS | C64: Usage Monitoring | D64: Recent SMS Usage | E64: 10/02/2017 | F64: Send an email to jonatan.moya@prosegur.com | G64: 50 messages in cycle to date | H64: Account: PROSEGUR ACTIVA ARGENTINA SA | I64: Yes
A65: PROSEGUR ACTIVA ARGENTINA SA | B65: Consumo en exceso de SMS | C65: Usage Monitoring | D65: Recent SMS Usage | E65: 09/03/2014 | F65: Send an email to sebastian.etcheverry@prosegur.com | G65: 50 messages in cycle to date | H65: Account: PROSEGUR ACTIVA ARGENTINA SA | I65: Yes
A66: PruebasIng | B66: Alerta Cambio de Plan | C66: SIM Provisioning | D66: SIM Rate Plan Change | E66: 09/18/2013 | F66: Send an email to ignacio.gasparini@claro.com.ar | G66: From JCN05 To JCN10 | H66: Account: PruebasIng | I66: Yes
A67: PruebasIng | B67: Cambio de Plan 6MB sin roaming | C67: Usage Monitoring | D67: Cycle To Date Data Usage | E67: 12/16/2013 | F67: Change the rate plan to "JCN05" | G67: Data usage exceeds a specified limit 6000 KB | H67: Account: PruebasIng; Sim Status: Activated; Customer: MKT Co | I67: Yes
A68: PruebasIng | B68: Cambio a Plan de 10MB | C68: Usage Monitoring | D68: Cycle To Date Data Usage | E68: 12/17/2013 | F68: Change the rate plan to "JCN10" | G68: Data usage exceeds a specified limit 8200 KB | H68: Account: PruebasIng | I68: Yes
A69: PruebasIng | B69: Cambio de IMEI | C69: Security | D69: IMEI Change | E69: 03/05/2014 | F69: Send an email to ignacio.gasparini@claro.com.ar | G69: Trigger when detecting an IMEI change in accounting start request | H69: Account: PruebasIng | I69: Yes
A70: QUALITY SYSTEMS GROUP SRL | B70: Consumo 25MB | C70: Usage Monitoring | D70: Cycle To Date Data Usage | E70: 09/09/2021 | F70: Send an email to administracion@qualitysystems.com.ar | G70: Data usage approaches its usage limit 25600 KB | H70: Account: QUALITY SYSTEMS GROUP SRL | I70: Yes
A71: QUALITY SYSTEMS GROUP SRL | B71: Bloqueo de excedente | C71: Usage Monitoring | D71: Cycle To Date Data Usage | E71: 03/21/2022 | F71: Change the SIM status to "Deactivated" | G71: Data usage approaches its usage limit 25600 KB | H71: Account: QUALITY SYSTEMS GROUP SRL | I71: Yes
A72: ROSARIO BUS SA | B72: Consumo Datos 250 mb | C72: Usage Monitoring | D72: Cycle To Date Data Usage | E72: 12/21/2018 | F72: Send an email to clarisa.livieri@rosariobus.com.ar | G72: Data usage exceeds a specified limit 256000 KB | H72: Account: ROSARIO BUS SA | I72: Yes
A73: ROSARIO BUS SA | B73: Consumo de datos mayores a 350 MB | C73: Usage Monitoring | D73: Cycle To Date Data Usage | E73: 04/22/2020 | F73: Send an email to clarisa.livieri@rosariobus.com.ar | G73: Data usage exceeds a specified limit 358400 KB | H73: Account: ROSARIO BUS SA | I73: Yes
A74: SEAC S.A. | B74: Control del uso - Desactivar | C74: Usage Monitoring | D74: Cycle To Date Data Usage | E74: 06/08/2015 | F74: Change the SIM status to "Deactivated" | G74: Data usage approaches its usage limit 1 KB | H74: Account: SEAC S.A. | I74: Yes
...

Sheet Hoja1
A1: Cluster 1 | B1: Cant. Planes | C1: Nombre planes
A2: DI BELLA, LUCAS GASTON | B2: 1 (JASC010) | C2: JASC010
A3: GCBA | B3: 2 (JAGC1GB y JASN010) | C3: JAGC1GB,JASN010
A4: VirtualPin S.A. | B4: 1 (JASC010) | C4: JASC010
A5: Grupo Margen | B5: 1 (JASC010) | C5: JASC010
A6: CIA Omnibus 25 de mayo | B6: 1 (JASC025) | C6: JASC025
A7: Desarrollos del Litoral | B7: 1 (JASC010) | C7: JASC010
A8: BIT S.A. | B8: 2 (JASC010 y JASC025) | C8: JASC010,JASC025
A9: TELPOP | B9: 3 (JASC010, JASC025, JASL010) | C9: JASC010,JASC025,JASL010
A10: Empresa distribuidora deenergia atlantic | B10: 1 (JASC025) | C10: JASC025
A11: A.C. SAT SRL | B11: 1 JASC010 | C11: JASC010
A12: TRANSPORTADORA GAS DEL NORTE | B12: 1 (JASC025) | C12: JASC025
... A104: OLEIROS SA | B104: 1 (LOJ015+) | C104: LOJ015+
